Workbook

Sheet Property-Definition
A1: performative | B1: argument | C1: direction | D1: key | E1: type | F1: value | G1: valueOptions | H1: AWB-Integration Bundle | I1: Done Server-Side | J1: Done Client-Side | K1: Description
A2: DB.SYSTEMS | C2: GET | D2: dbSystem[X] | E2: String | F2: e.g. 'Apache Derby', 'MariaDB', … | H2: de.enflexit.db.hibernate | I2: True | J2: True | K2: Get only. Probably returns several indexed properties. Returns all registered HibernateDatabaseServices with ther names.
A3: DB.SYSTEMS.PARAMETER | C3: GET | D3: dbSystem[X] | E3: String | F3: e.g. 'MariaDB' | H3: de.enflexit.db.hibernate | I3: True | J3: True
A4: DB.SYSTEMS.PARAMETER | C4: GET | D4: dbSystem[X].hibernate.connection.driver_class | E4: String | F4: e.g. 'org.mariadb.jdbc.Driver' | H4: de.enflexit.db.hibernate | I4: True | J4: True
A5: DB.SYSTEMS.PARAMETER | C5: GET | D5: dbSystem[X].hibernate.connection.url | E5: String | F5: e.g. 'jdbc:mariadb://localhost:3306/agentWorkbench?createDatabaseIfNotExist=true' | H5: de.enflexit.db.hibernate | I5: True | J5: True
A6: DB.SYSTEMS.PARAMETER | C6: GET | D6: dbSystem[X].hibernate.connection.url.mask | E6: String | F6: e.g. 'jdbc:mariadb://[HostOrIP]:[Port]/[Catalog]?createDatabaseIfNotExist=true' | H6: de.enflexit.db.hibernate | I6: True | J6: True
A7: DB.SYSTEMS.PARAMETER | C7: GET | D7: dbSystem[X].hibernate.default_catalog | E7: String | F7: e.g. 'agentWorkbench' | H7: de.enflexit.db.hibernate | I7: True | J7: True
A8: DB.SYSTEMS.PARAMETER | C8: GET | D8: dbSystem[X].hibernate.connection.username | E8: String | F8: e.g. 'admin' | H8: de.enflexit.db.hibernate | I8: True | J8: True
A9: DB.SYSTEMS.PARAMETER | C9: GET | D9: dbSystem[X].hibernate.connection.password | E9: String | F9: e.g. 'secret' | H9: de.enflexit.db.hibernate | I9: True | J9: True
A10: DB.FACTORIES | C10: GET | D10: factory[X] | E10: String | F10: e.g. 'de.enfexit.awb.bgsystem.db' | H10: de.enflexit.db.hibernate | I10: True | J10: True | K10: Returns all registered Hibernate database factories with their name.
A11: DB.FACTORIES | C11: GET | D11: factory[X].state | E11: String | F11: e.g.'Created' | G11: [NotAvailableYet (Not available yet), Destroyed (SessionFactory was destroyed), CheckDBConnection (Checking database connection ...), CheckDBConectionFailed (Database connection test failed!), InitializationProcessStarted (Initialize SessionFactory), InitializationProcessFailed (Initialization of SessionFactory failed), Created (Successfully Initialized)] | H11: de.enflexit.db.hibernate | I11: True | J11: True | K11: Returns the states of the corresponding factory (see value Options)
A12: DB.DERBY.NETWORKSERVER | C12: GET + SET | D12: isStartDerbyNetworkServer | E12: Boolean | F12: true | false | H12: de.enflexit.db.derby | I12: True | J12: True | K12: indicator to start a derby network server
A13: DB.DERBY.NETWORKSERVER | C13: GET + SET | D13: host-IP | E13: String | F13: localhost | H13: de.enflexit.db.derby | I13: True | J13: True | K13: Host or IP-Address
A14: DB.DERBY.NETWORKSERVER | C14: GET + SET | D14: port | E14: Integer | F14: 1527 | H14: de.enflexit.db.derby | I14: True | J14: True | K14: Port of the DB-Server
A15: DB.DERBY.NETWORKSERVER | C15: GET + SET | D15: userName | E15: String | F15: xxxxx | H15: de.enflexit.db.derby | I15: True | J15: True | K15: The username to access the DB-Server
A16: DB.DERBY.NETWORKSERVER | C16: GET + SET | D16: password | E16: String | F16: ****** | H16: de.enflexit.db.derby | I16: True | J16: True | K16: The password to access the DB-Server
A17: DB.CONN.GENERAL | C17: GET + SET | D17: useForEveryFactory | E17: Boolean | F17: true | false | H17: de.enflexit.db.hibernate | I17: True | J17: True | K17: Decides wether to use the general database connection settings for every db connection.
A18: DB.CONN.GENERAL | C18: GET + SET | D18: dbSystem | E18: String | F18: e.g. 'MariaDB' | H18: de.enflexit.db.hibernate | I18: True | J18: True | K18: The name of the database System
A19: DB.CONN.GENERAL | C19: GET + SET | D19: hibernate.connection.driver_class | E19: String | F19: e.g. 'org.mariadb.jdbc.Driver' | H19: de.enflexit.db.hibernate | I19: True | J19: True
A20: DB.CONN.GENERAL | C20: GET + SET | D20: hibernate.connection.url | E20: String | F20: e.g. 'jdbc:mariadb://myServer:1234/myDatabase?createDatabaseIfNotExist=true' | H20: de.enflexit.db.hibernate | I20: True | J20: True
A21: DB.CONN.GENERAL | C21: GET + SET | D21: hibernate.default_catalog | E21: String | F21: e.g. 'myDatabase' | H21: de.enflexit.db.hibernate | I21: True | J21: True
A22: DB.CONN.GENERAL | C22: GET + SET | D22: hibernate.connection.username | E22: String | F22: e.g. 'superUser' | H22: de.enflexit.db.hibernate | I22: True | J22: True
A23: DB.CONN.GENERAL | C23: GET + SET | D23: hibernate.connection.password | E23: String | F23: e.g. 'secretPassword' | H23: de.enflexit.db.hibernate | I23: True | J23: True
A24: DB.CONN.FACTORY.GET | C24: GET | D24: factory[X].factoryID | E24: String | F24: e.g. 'de.enflexit.awb.bgsystem.db' | H24: de.enflexit.db.hibernate | I24: True | J24: True | K24: Returns a list with all registered hibernate session factories
A25: DB.CONN.FACTORY.GET | C25: GET | D25: factory[X].dbSystem | E25: String | F25: e.g. 'MariaDB' | H25: de.enflexit.db.hibernate | I25: True | J25: True | K25: The database system currently selected within the factory
A26: DB.CONN.FACTORY.GET | C26: GET | D26: factory[X].hibernate.connection.driver_class | E26: String | F26: e.g. 'org.mariadb.jdbc.Driver' | H26: de.enflexit.db.hibernate | I26: True | J26: True
A27: DB.CONN.FACTORY.GET | C27: GET | D27: factory[X].hibernate.connection.url | E27: String | F27: e.g. 'jdbc:mariadb://myServer:1234/myDatabase?createDatabaseIfNotExist=true' | H27: de.enflexit.db.hibernate | I27: True | J27: True
A28: DB.CONN.FACTORY.GET | C28: GET | D28: factory[X].hibernate.default_catalog | E28: String | F28: e.g. 'myDatabase' | H28: de.enflexit.db.hibernate | I28: True | J28: True
A29: DB.CONN.FACTORY.GET | C29: GET | D29: factory[X].hibernate.connection.username | E29: String | F29: e.g. 'superUser' | H29: de.enflexit.db.hibernate | I29: True | J29: True
A30: DB.CONN.FACTORY.GET | C30: GET | D30: factory[X].hibernate.connection.password | E30: String | F30: e.g. 'secretPassword' | H30: de.enflexit.db.hibernate | I30: True | J30: True
A31: DB.CONN.FACTORY.SET | C31: SET | D31: factoryID | E31: String | F31: e.g. 'de.enflexit.awb.bgsystem.db' | H31: de.enflexit.db.hibernate | I31: True | J31: True
A32: DB.CONN.FACTORY.SET | C32: SET | D32: dbSystem | E32: String | F32: e.g. 'MariaDB' | H32: de.enflexit.db.hibernate | I32: True | J32: True
A33: DB.CONN.FACTORY.SET | C33: SET | D33: hibernate.connection.driver_class | E33: String | F33: e.g. 'org.mariadb.jdbc.Driver' | H33: de.enflexit.db.hibernate | I33: True | J33: True
A34: DB.CONN.FACTORY.SET | C34: SET | D34: hibernate.connection.url | E34: String | F34: e.g. 'jdbc:mariadb://myServer:1234/myDatabase?createDatabaseIfNotExist=true' | H34: de.enflexit.db.hibernate | I34: True | J34: True
A35: DB.CONN.FACTORY.SET | C35: SET | D35: hibernate.default_catalog | E35: String | F35: e.g. 'myDatabase' | H35: de.enflexit.db.hibernate | I35: True | J35: True
A36: DB.CONN.FACTORY.SET | C36: SET | D36: hibernate.connection.username | E36: String | F36: e.g. 'superUser' | H36: de.enflexit.db.hibernate | I36: True | J36: True
A37: DB.CONN.FACTORY.SET | C37: SET | D37: hibernate.connection.password | E37: String | F37: e.g. 'secretPassword' | H37: de.enflexit.db.hibernate | I37: True | J37: True
... A43: DB.CONN.TEST | C43: SET | D43: hibernate.connection.password | E43: String | F43: e.g. 'secretPassword' | H43: de.enflexit.db.hibernate | I43: True | J43: True
A44: EXEC.MODE | C44: GET+SET | D44: exec.mode | E44: String | F44: e.g. 'Application' | G44: APPLICATION, SERVER, SERVER_MASTER, SERVER_SLAVE, DEVICE_SYSTEM | H44: de.enflexit.awb.core | I44: True | J44: True
A45: EXEC.MODE | C45: GET+SET | D45: server.master.url | E45: String | F45: e.g. 'HTTP//:myServer:1099/JADE' | H45: de.enflexit.awb.core | I45: True | J45: True
...

Sheet Java-Code
A1: ='Property-Definition'!A1 -> performative | B1: Constant-Definition
A2: ='Property-Definition'!A2 -> DB.SYSTEMS | B2: ="public final static String " & UPPER( SUBSTITUTE( SUBSTITUTE('Property-Definition'!D2,"[X]",""),".","_") ) & " = " & CHAR(34) & 'Property-Definition'!D2 & CHAR(34) & ";" -> public final static String DBSYSTEM = "dbSystem[X]";
A3: ='Property-Definition'!A3 -> DB.SYSTEMS.PARAMETER | B3: ="public final static String " & UPPER( SUBSTITUTE( SUBSTITUTE('Property-Definition'!D3,"[X]",""),".","_") ) & " = " & CHAR(34) & 'Property-Definition'!D3 & CHAR(34) & ";" -> public final static String DBSYSTEM = "dbSystem[X]";
A4: ='Property-Definition'!A4 -> DB.SYSTEMS.PARAMETER | B4: ="public final static String " & UPPER( SUBSTITUTE( SUBSTITUTE('Property-Definition'!D4,"[X]",""),".","_") ) & " = " & CHAR(34) & 'Property-Definition'!D4 & CHAR(34) & ";" -> public final static String DBSYSTEM_HIBERNATE_CONNECTION_DRIVER_CLASS = "dbSystem[X].hibernate.connection.driver_class";
A5: ='Property-Definition'!A5 -> DB.SYSTEMS.PARAMETER | B5: ="public final static String " & UPPER( SUBSTITUTE( SUBSTITUTE('Property-Definition'!D5,"[X]",""),".","_") ) & " = " & CHAR(34) & 'Property-Definition'!D5 & CHAR(34) & ";" -> public final static String DBSYSTEM_HIBERNATE_CONNECTION_URL = "dbSystem[X].hibernate.connection.url";
A6: ='Property-Definition'!A6 -> DB.SYSTEMS.PARAMETER | B6: ="public final static String " & UPPER( SUBSTITUTE( SUBSTITUTE('Property-Definition'!D6,"[X]",""),".","_") ) & " = " & CHAR(34) & 'Property-Definition'!D6 & CHAR(34) & ";" -> public final static String DBSYSTEM_HIBERNATE_CONNECTION_URL_MASK = "dbSystem[X].hibernate.connection.url.mask";
A7: ='Property-Definition'!A7 -> DB.SYSTEMS.PARAMETER | B7: ="public final static String " & UPPER( SUBSTITUTE( SUBSTITUTE('Property-Definition'!D7,"[X]",""),".","_") ) & " = " & CHAR(34) & 'Property-Definition'!D7 & CHAR(34) & ";" -> public final static String DBSYSTEM_HIBERNATE_DEFAULT_CATALOG = "dbSystem[X].hibernate.default_catalog";
A8: ='Property-Definition'!A8 -> DB.SYSTEMS.PARAMETER | B8: ="public final static String " & UPPER( SUBSTITUTE( SUBSTITUTE('Property-Definition'!D8,"[X]",""),".","_") ) & " = " & CHAR(34) & 'Property-Definition'!D8 & CHAR(34) & ";" -> public final static String DBSYSTEM_HIBERNATE_CONNECTION_USERNAME = "dbSystem[X].hibernate.connection.username";
A9: ='Property-Definition'!A9 -> DB.SYSTEMS.PARAMETER | B9: ="public final static String " & UPPER( SUBSTITUTE( SUBSTITUTE('Property-Definition'!D9,"[X]",""),".","_") ) & " = " & CHAR(34) & 'Property-Definition'!D9 & CHAR(34) & ";" -> public final static String DBSYSTEM_HIBERNATE_CONNECTION_PASSWORD = "dbSystem[X].hibernate.connection.password";
A10: ='Property-Definition'!A10 -> DB.FACTORIES | B10: ="public final static String " & UPPER( SUBSTITUTE( SUBSTITUTE('Property-Definition'!D10,"[X]",""),".","_") ) & " = " & CHAR(34) & 'Property-Definition'!D10 & CHAR(34) & ";" -> public final static String FACTORY = "factory[X]";
A11: ='Property-Definition'!A11 -> DB.FACTORIES | B11: ="public final static String " & UPPER( SUBSTITUTE( SUBSTITUTE('Property-Definition'!D11,"[X]",""),".","_") ) & " = " & CHAR(34) & 'Property-Definition'!D11 & CHAR(34) & ";" -> public final static String FACTORY_STATE = "factory[X].state";
A12: ='Property-Definition'!A12 -> DB.DERBY.NETWORKSERVER | B12: ="public final static String " & UPPER( SUBSTITUTE( SUBSTITUTE('Property-Definition'!D12,"[X]",""),".","_") ) & " = " & CHAR(34) & 'Property-Definition'!D12 & CHAR(34) & ";" -> public final static String ISSTARTDERBYNETWORKSERVER = "isStartDerbyNetworkServer";
A13: ='Property-Definition'!A13 -> DB.DERBY.NETWORKSERVER | B13: ="public final static String " & UPPER( SUBSTITUTE( SUBSTITUTE('Property-Definition'!D13,"[X]",""),".","_") ) & " = " & CHAR(34) & 'Property-Definition'!D13 & CHAR(34) & ";" -> public final static String HOST-IP = "host-IP";
... A59: ='Property-Definition'!A59 -> EXEC.MODE | B59: ="public final static String " & UPPER( SUBSTITUTE( SUBSTITUTE('Property-Definition'!D59,"[X]",""),".","_") ) & " = " & CHAR(34) & 'Property-Definition'!D59 & CHAR(34) & ";" -> public final static String FACTORY_ID = "factory_id";
A60: ='Property-Definition'!#REF! -> #REF! | B60: ="public final static String " & UPPER( SUBSTITUTE( SUBSTITUTE('Property-Definition'!#REF!,"[X]",""),".","_") ) & " = " & CHAR(34) & 'Property-Definition'!#REF! & CHAR(34) & ";" -> #REF!
A61: ='Property-Definition'!A60 -> AWB.AGENTS | B61: ="public final static String " & UPPER( SUBSTITUTE( SUBSTITUTE('Property-Definition'!D60,"[X]",""),".","_") ) & " = " & CHAR(34) & 'Property-Definition'!D60 & CHAR(34) & ";" -> public final static String AGENT_CLASSNAME = "agent[X].classname";
A62: ='Property-Definition'!A61 -> PROJECTS | B62: ="public final static String " & UPPER( SUBSTITUTE( SUBSTITUTE('Property-Definition'!D61,"[X]",""),".","_") ) & " = " & CHAR(34) & 'Property-Definition'!D61 & CHAR(34) & ";" -> public final static String PROJECT = "project[X]";
A63: ='Property-Definition'!A62 -> PROJECT.SETUPS[X] | B63: ="public final static String " & UPPER( SUBSTITUTE( SUBSTITUTE('Property-Definition'!D62,"[X]",""),".","_") ) & " = " & CHAR(34) & 'Property-Definition'!D62 & CHAR(34) & ";" -> public final static String PROJECT_SETUP = "project[X].setup[X]";
A64: ='Property-Definition'!A63 -> EXEC.MASTER.SLAVES.GET | B64: ="public final static String " & UPPER( SUBSTITUTE( SUBSTITUTE('Property-Definition'!D63,"[X]",""),".","_") ) & " = " & CHAR(34) & 'Property-Definition'!D63 & CHAR(34) & ";" -> public final static String BGPLATFORM_CONTACTAGENT = "bgplatform[X].contactagent";
A65: ='Property-Definition'!A60 -> AWB.AGENTS | B65: ="public final static String " & UPPER( SUBSTITUTE( SUBSTITUTE('Property-Definition'!D64,"[X]",""),".","_") ) & " = " & CHAR(34) & 'Property-Definition'!D64 & CHAR(34) & ";" -> public final static String BGPLATFORM_PLATFORMNAME = "bgplatform[X].platformname";
A66: ='Property-Definition'!A61 -> PROJECTS | B66: ="public final static String " & UPPER( SUBSTITUTE( SUBSTITUTE('Property-Definition'!D65,"[X]",""),".","_") ) & " = " & CHAR(34) & 'Property-Definition'!D65 & CHAR(34) & ";" -> public final static String BGPLATFORM_SERVER = "bgplatform[X].server";
A67: ='Property-Definition'!A62 -> PROJECT.SETUPS[X] | B67: ="public final static String " & UPPER( SUBSTITUTE( SUBSTITUTE('Property-Definition'!D66,"[X]",""),".","_") ) & " = " & CHAR(34) & 'Property-Definition'!D66 & CHAR(34) & ";" -> public final static String BGPLATFORM_IPADDRESS = "bgplatform[X].ipaddress";
A68: ='Property-Definition'!A67 -> EXEC.MASTER.SLAVES.GET | B68: ="public final static String " & UPPER( SUBSTITUTE( SUBSTITUTE('Property-Definition'!D67,"[X]",""),".","_") ) & " = " & CHAR(34) & 'Property-Definition'!D67 & CHAR(34) & ";" -> public final static String BGPLATFORM_URL = "bgplatform[X].url";
A69: ='Property-Definition'!A68 -> EXEC.MASTER.SLAVES.GET | B69: ="public final static String " & UPPER( SUBSTITUTE( SUBSTITUTE('Property-Definition'!D68,"[X]",""),".","_") ) & " = " & CHAR(34) & 'Property-Definition'!D68 & CHAR(34) & ";" -> public final static String BGPLATFORM_JADEPORT = "bgplatform[X].jadeport";
A70: ='Property-Definition'!A69 -> EXEC.MASTER.SLAVES.GET | B70: ="public final static String " & UPPER( SUBSTITUTE( SUBSTITUTE('Property-Definition'!D69,"[X]",""),".","_") ) & " = " & CHAR(34) & 'Property-Definition'!D69 & CHAR(34) & ";" -> public final static String BGPLATFORM_HTTPMTP = "bgplatform[X].httpmtp";
A71: ='Property-Definition'!A70 -> EXEC.MASTER.SLAVES.GET | B71: ="public final static String " & UPPER( SUBSTITUTE( SUBSTITUTE('Property-Definition'!D70,"[X]",""),".","_") ) & " = " & CHAR(34) & 'Property-Definition'!D70 & CHAR(34) & ";" -> public final static String BGPLATFORM_VERSIONMAJOR = "bgplatform[X].versionmajor";
A72: ='Property-Definition'!A71 -> EXEC.MASTER.SLAVES.GET | B72: ="public final static String " & UPPER( SUBSTITUTE( SUBSTITUTE('Property-Definition'!D71,"[X]",""),".","_") ) & " = " & CHAR(34) & 'Property-Definition'!D71 & CHAR(34) & ";" -> public final static String BGPLATFORM_VERSIONMINOR = "bgplatform[X].versionminor";
A73: ='Property-Definition'!A72 -> EXEC.MASTER.SLAVES.GET | B73: ="public final static String " & UPPER( SUBSTITUTE( SUBSTITUTE('Property-Definition'!D72,"[X]",""),".","_") ) & " = " & CHAR(34) & 'Property-Definition'!D72 & CHAR(34) & ";" -> public final static String BGPLATFORM_VERSIONMICRO = "bgplatform[X].versionmicro";
A74: ='Property-Definition'!A73 -> EXEC.MASTER.SLAVES.GET | B74: ="public final static String " & UPPER( SUBSTITUTE( SUBSTITUTE('Property-Definition'!D73,"[X]",""),".","_") ) & " = " & CHAR(34) & 'Property-Definition'!D73 & CHAR(34) & ";" -> public final static String BGPLATFORM_VERSIONBUILD = "bgplatform[X].versionbuild";
A75: ='Property-Definition'!A74 -> EXEC.MASTER.SLAVES.GET | B75: ="public final static String " & UPPER( SUBSTITUTE( SUBSTITUTE('Property-Definition'!D74,"[X]",""),".","_") ) & " = " & CHAR(34) & 'Property-Definition'!D74 & CHAR(34) & ";" -> public final static String BGPLATFORM_OS_NAME = "bgplatform[X].os.name";
A76: ='Property-Definition'!A75 -> EXEC.MASTER.SLAVES.GET | B76: ="public final static String " & UPPER( SUBSTITUTE( SUBSTITUTE('Property-Definition'!D75,"[X]",""),".","_") ) & " = " & CHAR(34) & 'Property-Definition'!D75 & CHAR(34) & ";" -> public final static String BGPLATFORM_OS_VERSION = "bgplatform[X].os.version";
A77: ='Property-Definition'!A76 -> EXEC.MASTER.SLAVES.GET | B77: ="public final static String " & UPPER( SUBSTITUTE( SUBSTITUTE('Property-Definition'!D76,"[X]",""),".","_") ) & " = " & CHAR(34) & 'Property-Definition'!D76 & CHAR(34) & ";" -> public final static String BGPLATFORM_OS_ARCHITECTURE = "bgplatform[X].os.architecture";
A78: ='Property-Definition'!A77 -> EXEC.MASTER.SLAVES.GET | B78: ="public final static String " & UPPER( SUBSTITUTE( SUBSTITUTE('Property-Definition'!D77,"[X]",""),".","_") ) & " = " & CHAR(34) & 'Property-Definition'!D77 & CHAR(34) & ";" -> public final static String BGPLATFORM_CPU_NAME = "bgplatform[X].cpu.name";
A79: ='Property-Definition'!A78 -> EXEC.MASTER.SLAVES.GET | B79: ="public final static String " & UPPER( SUBSTITUTE( SUBSTITUTE('Property-Definition'!D78,"[X]",""),".","_") ) & " = " & CHAR(34) & 'Property-Definition'!D78 & CHAR(34) & ";" -> public final static String BGPLATFORM_CPU_NUMLOGICAL = "bgplatform[X].cpu.numlogical";
... A97: ='Property-Definition'!A96 -> UPDATE.BACKEND.CHECK | B97: ="public final static String " & UPPER( SUBSTITUTE( SUBSTITUTE('Property-Definition'!D96,"[X]",""),".","_") ) & " = " & CHAR(34) & 'Property-Definition'!D96 & CHAR(34) & ";" -> public final static String UPDATECHECK_BACKEND_LASTCHECK = "updatecheck.backend.lastcheck";
A98: ='Property-Definition'!#REF! -> #REF! | B98: ="public final static String " & UPPER( SUBSTITUTE( SUBSTITUTE('Property-Definition'!#REF!,"[X]",""),".","_") ) & " = " & CHAR(34) & 'Property-Definition'!#REF! & CHAR(34) & ";" -> #REF!
A99: ='Property-Definition'!A100 -> UPDATE.FRONTEND.CHECK | B99: ="public final static String " & UPPER( SUBSTITUTE( SUBSTITUTE('Property-Definition'!D100,"[X]",""),".","_") ) & " = " & CHAR(34) & 'Property-Definition'!D100 & CHAR(34) & ";" -> public final static String UPDATECHECK_FRONTEND_ISPENDING = "updatecheck.frontend.ispending";
A100: ='Property-Definition'!A101 -> UPDATE.FRONTEND.CHECK | B100: ="public final static String " & UPPER( SUBSTITUTE( SUBSTITUTE('Property-Definition'!D101,"[X]",""),".","_") ) & " = " & CHAR(34) & 'Property-Definition'!D101 & CHAR(34) & ";" -> public final static String UPDATECHECK_FRONTEND_ISAVAILABLE = "updatecheck.frontend.isavailable";
A101: ='Property-Definition'!A102 -> UPDATE.FRONTEND.CHECK | B101: ="public final static String " & UPPER( SUBSTITUTE( SUBSTITUTE('Property-Definition'!D102,"[X]",""),".","_") ) & " = " & CHAR(34) & 'Property-Definition'!D102 & CHAR(34) & ";" -> public final static String UPDATECHECK_FRONTEND_LASTCHECK = "updatecheck.frontend.lastcheck";
A102: ='Property-Definition'!A104 -> UPDATE.FRONTEND.CHECK | B102: ="public final static String " & UPPER( SUBSTITUTE( SUBSTITUTE('Property-Definition'!D104,"[X]",""),".","_") ) & " = " & CHAR(34) & 'Property-Definition'!D104 & CHAR(34) & ";" -> public final static String UPDATECHECK_FRONTEND_NEWVERSION = "updatecheck.frontend.newversion";
...
